2024-08-21 00:00:28.467 - componentLogger - Launcher.startup - ERROR - 组件注册运行发生异常:<AioRpcError of RPC that terminated with:
	status = StatusCode.UNKNOWN
	details = ""
	debug_error_string = "UNKNOWN:Error received from peer  {created_time:"2024-08-20T16:00:28.4230536+00:00", grpc_status:2, grpc_message:""}"
>
Traceback (most recent call last):
  File "G:\hardSoft\app\CentralController\ApplicationFramework\launcher\Launcher.py", line 89, in startup
    await self.__application_task
  File "G:\hardSoft\app\CentralController\CentralController/application\ApplicationImplement.py", line 197, in run
    await process_manager.startup()
  File "G:\hardSoft\app\CentralController\CentralController\service\ProcessManager.py", line 48, in startup
    await self.__component_framework.bind_message(MessageBindingModel(message_key=message_key))
  File "G:\hardSoft\app\CentralController\ApplicationFramework\facade\ComponentFrameworkImplement.py", line 62, in bind_message
    new_message_model = await self.__message_component.bind_message(
  File "G:\hardSoft\app\CentralController\componentframework\control\MessageManagerInterfaceImpl.py", line 36, in bind_message
    self.bind_message_result = await self.__message_forwarder.bind_message(message_model)
  File "G:\hardSoft\app\CentralController\componentframework\service\MessageManagerService.py", line 47, in bind_message
    self.bind_message_result = await self.__message_forwarder.bind_message(message_model)
  File "G:\hardSoft\app\CentralController\componentframework\facadeImpl\MessageManagerGrpcFacadeImpl.py", line 43, in bind_message
    response = await self.stub.BindMessage(request)
  File "G:\hardSoft\Python310\lib\site-packages\grpc\aio\_call.py", line 318, in __await__
    raise _create_rpc_error(
grpc.aio._call.AioRpcError: <AioRpcError of RPC that terminated with:
	status = StatusCode.UNKNOWN
	details = ""
	debug_error_string = "UNKNOWN:Error received from peer  {created_time:"2024-08-20T16:00:28.4230536+00:00", grpc_status:2, grpc_message:""}"
>
