2024-08-18 20:17:51.932 - componentLogger - Launcher.startup - ERROR - 组件注册运行发生异常:<AioRpcError of RPC that terminated with:
	status = StatusCode.UNKNOWN
	details = ""
	debug_error_string = "UNKNOWN:Error received from peer  {grpc_message:"", grpc_status:2, created_time:"2024-08-18T12:17:51.9164204+00:00"}"
>
Traceback (most recent call last):
  File "F:\hardSoft\app\CentralController\ApplicationFramework\launcher\Launcher.py", line 86, in startup
    await self.__component_framework.register_component(component_model)
  File "F:\hardSoft\app\CentralController\ApplicationFramework\facade\ComponentFrameworkImplement.py", line 93, in register_component
    registered_component: ComponentModel_CCM = await self.__component_manager.component_register(
  File "F:\hardSoft\app\CentralController\componentframework\control\ComponentManagerInterfaceImpl.py", line 44, in component_register
    self.component_register_result = await self.__component_forwarder.component_register(component_model)
  File "F:\hardSoft\app\CentralController\componentframework\service\ComponentManagerService.py", line 48, in component_register
    self.component_register_result = await self.__component_forwarder.component_register(component_model)
  File "F:\hardSoft\app\CentralController\componentframework\facadeImpl\ComponentManagerFacadeImpl.py", line 58, in component_register
    response = await self.stub.RegisterComponent(request)
  File "C:\Users\st1\AppData\Local\Programs\Python\Python310\lib\site-packages\grpc\aio\_call.py", line 327, in __await__
    raise _create_rpc_error(
grpc.aio._call.AioRpcError: <AioRpcError of RPC that terminated with:
	status = StatusCode.UNKNOWN
	details = ""
	debug_error_string = "UNKNOWN:Error received from peer  {grpc_message:"", grpc_status:2, created_time:"2024-08-18T12:17:51.9164204+00:00"}"
>
2024-08-18 20:17:54.244 - componentLogger - Launcher.shutdown - ERROR - 组件注销发生异常:<AioRpcError of RPC that terminated with:
	status = StatusCode.UNAVAILABLE
	details = "failed to connect to all addresses; last error: UNAVAILABLE: ipv4:127.0.0.1:9000: ConnectEx: Connection refused (No connection could be made because the target machine actively refused it.
 -- 10061)"
	debug_error_string = "UNKNOWN:Error received from peer  {grpc_message:"failed to connect to all addresses; last error: UNAVAILABLE: ipv4:127.0.0.1:9000: ConnectEx: Connection refused (No connection could be made because the target machine actively refused it.\r\n -- 10061)", grpc_status:14, created_time:"2024-08-18T12:17:54.2346098+00:00"}"
>
Traceback (most recent call last):
  File "F:\hardSoft\app\CentralController\ApplicationFramework\launcher\Launcher.py", line 97, in shutdown
    await self.__component_framework.unregister_component()
  File "F:\hardSoft\app\CentralController\ApplicationFramework\facade\ComponentFrameworkImplement.py", line 105, in unregister_component
    await self.__component_manager.unregister_component()
  File "F:\hardSoft\app\CentralController\componentframework\control\ComponentManagerInterfaceImpl.py", line 129, in unregister_component
    self.unregister_component_result = await self.__component_forwarder.unregister_component()
  File "F:\hardSoft\app\CentralController\componentframework\service\ComponentManagerService.py", line 133, in unregister_component
    self.unregister_component_result = await self.__component_forwarder.unregister_component()
  File "F:\hardSoft\app\CentralController\componentframework\facadeImpl\ComponentManagerFacadeImpl.py", line 146, in unregister_component
    response = await self.stub.UnregisterComponent(request)
  File "C:\Users\st1\AppData\Local\Programs\Python\Python310\lib\site-packages\grpc\aio\_call.py", line 327, in __await__
    raise _create_rpc_error(
grpc.aio._call.AioRpcError: <AioRpcError of RPC that terminated with:
	status = StatusCode.UNAVAILABLE
	details = "failed to connect to all addresses; last error: UNAVAILABLE: ipv4:127.0.0.1:9000: ConnectEx: Connection refused (No connection could be made because the target machine actively refused it.
 -- 10061)"
	debug_error_string = "UNKNOWN:Error received from peer  {grpc_message:"failed to connect to all addresses; last error: UNAVAILABLE: ipv4:127.0.0.1:9000: ConnectEx: Connection refused (No connection could be made because the target machine actively refused it.\r\n -- 10061)", grpc_status:14, created_time:"2024-08-18T12:17:54.2346098+00:00"}"
>
