2024-08-18 15:30:47.596 - componentLogger - Launcher.startup - ERROR - 组件注册运行发生异常:<AioRpcError of RPC that terminated with:
	status = StatusCode.UNAVAILABLE
	details = "failed to connect to all addresses; last error: UNAVAILABLE: ipv4:127.0.0.1:9002: ConnectEx: Connection refused (No connection could be made because the target machine actively refused it.
 -- 10061)"
	debug_error_string = "UNKNOWN:Error received from peer  {created_time:"2024-08-18T07:30:47.5674506+00:00", grpc_status:14, grpc_message:"failed to connect to all addresses; last error: UNAVAILABLE: ipv4:127.0.0.1:9002: ConnectEx: Connection refused (No connection could be made because the target machine actively refused it.\r\n -- 10061)"}"
>
Traceback (most recent call last):
  File "C:\Users\st1\Desktop\2024bci_group3\2024bci_group2\2024bci_group2\Collector\ApplicationFramework\launcher\Launcher.py", line 86, in startup
    await self.__component_framework.register_component(component_model)
  File "C:\Users\st1\Desktop\2024bci_group3\2024bci_group2\2024bci_group2\Collector\ApplicationFramework\facade\ComponentFrameworkImplement.py", line 93, in register_component
    registered_component: ComponentModel_CCM = await self.__component_manager.component_register(
  File "C:\Users\st1\Desktop\2024bci_group3\2024bci_group2\2024bci_group2\Collector\componentframework\control\ComponentManagerInterfaceImpl.py", line 44, in component_register
    self.component_register_result = await self.__component_forwarder.component_register(component_model)
  File "C:\Users\st1\Desktop\2024bci_group3\2024bci_group2\2024bci_group2\Collector\componentframework\service\ComponentManagerService.py", line 48, in component_register
    self.component_register_result = await self.__component_forwarder.component_register(component_model)
  File "C:\Users\st1\Desktop\2024bci_group3\2024bci_group2\2024bci_group2\Collector\componentframework\facadeImpl\ComponentManagerFacadeImpl.py", line 57, in component_register
    response = await self.stub.RegisterComponent(request)
  File "C:\Users\st1\AppData\Local\Programs\Python\Python310\lib\site-packages\grpc\aio\_call.py", line 327, in __await__
    raise _create_rpc_error(
grpc.aio._call.AioRpcError: <AioRpcError of RPC that terminated with:
	status = StatusCode.UNAVAILABLE
	details = "failed to connect to all addresses; last error: UNAVAILABLE: ipv4:127.0.0.1:9002: ConnectEx: Connection refused (No connection could be made because the target machine actively refused it.
 -- 10061)"
	debug_error_string = "UNKNOWN:Error received from peer  {created_time:"2024-08-18T07:30:47.5674506+00:00", grpc_status:14, grpc_message:"failed to connect to all addresses; last error: UNAVAILABLE: ipv4:127.0.0.1:9002: ConnectEx: Connection refused (No connection could be made because the target machine actively refused it.\r\n -- 10061)"}"
>
2024-08-18 15:30:47.644 - componentLogger - Launcher.shutdown - ERROR - 组件注销发生异常:<AioRpcError of RPC that terminated with:
	status = StatusCode.UNAVAILABLE
	details = "failed to connect to all addresses; last error: UNAVAILABLE: ipv4:127.0.0.1:9002: ConnectEx: Connection refused (No connection could be made because the target machine actively refused it.
 -- 10061)"
	debug_error_string = "UNKNOWN:Error received from peer  {grpc_message:"failed to connect to all addresses; last error: UNAVAILABLE: ipv4:127.0.0.1:9002: ConnectEx: Connection refused (No connection could be made because the target machine actively refused it.\r\n -- 10061)", grpc_status:14, created_time:"2024-08-18T07:30:47.6194277+00:00"}"
>
Traceback (most recent call last):
  File "C:\Users\st1\Desktop\2024bci_group3\2024bci_group2\2024bci_group2\Collector\ApplicationFramework\launcher\Launcher.py", line 97, in shutdown
    await self.__component_framework.unregister_component()
  File "C:\Users\st1\Desktop\2024bci_group3\2024bci_group2\2024bci_group2\Collector\ApplicationFramework\facade\ComponentFrameworkImplement.py", line 105, in unregister_component
    await self.__component_manager.unregister_component()
  File "C:\Users\st1\Desktop\2024bci_group3\2024bci_group2\2024bci_group2\Collector\componentframework\control\ComponentManagerInterfaceImpl.py", line 129, in unregister_component
    self.unregister_component_result = await self.__component_forwarder.unregister_component()
  File "C:\Users\st1\Desktop\2024bci_group3\2024bci_group2\2024bci_group2\Collector\componentframework\service\ComponentManagerService.py", line 133, in unregister_component
    self.unregister_component_result = await self.__component_forwarder.unregister_component()
  File "C:\Users\st1\Desktop\2024bci_group3\2024bci_group2\2024bci_group2\Collector\componentframework\facadeImpl\ComponentManagerFacadeImpl.py", line 145, in unregister_component
    response = await self.stub.UnregisterComponent(request)
  File "C:\Users\st1\AppData\Local\Programs\Python\Python310\lib\site-packages\grpc\aio\_call.py", line 327, in __await__
    raise _create_rpc_error(
grpc.aio._call.AioRpcError: <AioRpcError of RPC that terminated with:
	status = StatusCode.UNAVAILABLE
	details = "failed to connect to all addresses; last error: UNAVAILABLE: ipv4:127.0.0.1:9002: ConnectEx: Connection refused (No connection could be made because the target machine actively refused it.
 -- 10061)"
	debug_error_string = "UNKNOWN:Error received from peer  {grpc_message:"failed to connect to all addresses; last error: UNAVAILABLE: ipv4:127.0.0.1:9002: ConnectEx: Connection refused (No connection could be made because the target machine actively refused it.\r\n -- 10061)", grpc_status:14, created_time:"2024-08-18T07:30:47.6194277+00:00"}"
>
2024-08-18 19:01:27.250 - componentLogger - Launcher.startup - ERROR - 组件注册运行发生异常:<AioRpcError of RPC that terminated with:
	status = StatusCode.UNKNOWN
	details = ""
	debug_error_string = "UNKNOWN:Error received from peer  {grpc_message:"", grpc_status:2, created_time:"2024-08-18T11:01:27.2385041+00:00"}"
>
Traceback (most recent call last):
  File "C:\Users\st1\Desktop\2024bci_group3\2024bci_group2\2024bci_group2\Collector\ApplicationFramework\launcher\Launcher.py", line 86, in startup
    await self.__component_framework.register_component(component_model)
  File "C:\Users\st1\Desktop\2024bci_group3\2024bci_group2\2024bci_group2\Collector\ApplicationFramework\facade\ComponentFrameworkImplement.py", line 93, in register_component
    registered_component: ComponentModel_CCM = await self.__component_manager.component_register(
  File "C:\Users\st1\Desktop\2024bci_group3\2024bci_group2\2024bci_group2\Collector\componentframework\control\ComponentManagerInterfaceImpl.py", line 44, in component_register
    self.component_register_result = await self.__component_forwarder.component_register(component_model)
  File "C:\Users\st1\Desktop\2024bci_group3\2024bci_group2\2024bci_group2\Collector\componentframework\service\ComponentManagerService.py", line 48, in component_register
    self.component_register_result = await self.__component_forwarder.component_register(component_model)
  File "C:\Users\st1\Desktop\2024bci_group3\2024bci_group2\2024bci_group2\Collector\componentframework\facadeImpl\ComponentManagerFacadeImpl.py", line 57, in component_register
    response = await self.stub.RegisterComponent(request)
  File "C:\Users\st1\AppData\Local\Programs\Python\Python310\lib\site-packages\grpc\aio\_call.py", line 327, in __await__
    raise _create_rpc_error(
grpc.aio._call.AioRpcError: <AioRpcError of RPC that terminated with:
	status = StatusCode.UNKNOWN
	details = ""
	debug_error_string = "UNKNOWN:Error received from peer  {grpc_message:"", grpc_status:2, created_time:"2024-08-18T11:01:27.2385041+00:00"}"
>
2024-08-18 19:01:27.291 - componentLogger - Launcher.shutdown - ERROR - 组件注销发生异常:<AioRpcError of RPC that terminated with:
	status = StatusCode.UNKNOWN
	details = ""
	debug_error_string = "UNKNOWN:Error received from peer  {created_time:"2024-08-18T11:01:27.2802781+00:00", grpc_status:2, grpc_message:""}"
>
Traceback (most recent call last):
  File "C:\Users\st1\Desktop\2024bci_group3\2024bci_group2\2024bci_group2\Collector\ApplicationFramework\launcher\Launcher.py", line 97, in shutdown
    await self.__component_framework.unregister_component()
  File "C:\Users\st1\Desktop\2024bci_group3\2024bci_group2\2024bci_group2\Collector\ApplicationFramework\facade\ComponentFrameworkImplement.py", line 105, in unregister_component
    await self.__component_manager.unregister_component()
  File "C:\Users\st1\Desktop\2024bci_group3\2024bci_group2\2024bci_group2\Collector\componentframework\control\ComponentManagerInterfaceImpl.py", line 129, in unregister_component
    self.unregister_component_result = await self.__component_forwarder.unregister_component()
  File "C:\Users\st1\Desktop\2024bci_group3\2024bci_group2\2024bci_group2\Collector\componentframework\service\ComponentManagerService.py", line 133, in unregister_component
    self.unregister_component_result = await self.__component_forwarder.unregister_component()
  File "C:\Users\st1\Desktop\2024bci_group3\2024bci_group2\2024bci_group2\Collector\componentframework\facadeImpl\ComponentManagerFacadeImpl.py", line 145, in unregister_component
    response = await self.stub.UnregisterComponent(request)
  File "C:\Users\st1\AppData\Local\Programs\Python\Python310\lib\site-packages\grpc\aio\_call.py", line 327, in __await__
    raise _create_rpc_error(
grpc.aio._call.AioRpcError: <AioRpcError of RPC that terminated with:
	status = StatusCode.UNKNOWN
	details = ""
	debug_error_string = "UNKNOWN:Error received from peer  {created_time:"2024-08-18T11:01:27.2802781+00:00", grpc_status:2, grpc_message:""}"
>
2024-08-18 20:28:00.893 - componentLogger - Launcher.startup - ERROR - 组件注册运行发生异常:'HardwareCompetitionDataSender' object has no attribute 'set_receiver_transponder'
Traceback (most recent call last):
  File "F:\hardSoft\app\Collector\ApplicationFramework\launcher\Launcher.py", line 89, in startup
    await self.__application_task
  File "F:\hardSoft\app\Collector\Collector/application\ApplicationImplement.py", line 155, in run
    await self.__receiver_manager.startup()
  File "F:\hardSoft\app\Collector\Collector\service\ReceiverManager.py", line 45, in startup
    instance.set_receiver_transponder(self.__business_manager)
AttributeError: 'HardwareCompetitionDataSender' object has no attribute 'set_receiver_transponder'
2024-08-18 20:28:41.764 - componentLogger - Launcher.startup - ERROR - 组件注册运行发生异常:'HardwareCompetitionDataSender' object has no attribute 'set_receiver_transponder'
Traceback (most recent call last):
  File "F:\hardSoft\app\Collector\ApplicationFramework\launcher\Launcher.py", line 89, in startup
    await self.__application_task
  File "F:\hardSoft\app\Collector\Collector/application\ApplicationImplement.py", line 155, in run
    await self.__receiver_manager.startup()
  File "F:\hardSoft\app\Collector\Collector\service\ReceiverManager.py", line 45, in startup
    instance.set_receiver_transponder(self.__business_manager)
AttributeError: 'HardwareCompetitionDataSender' object has no attribute 'set_receiver_transponder'
2024-08-18 20:30:10.218 - componentLogger - Launcher.startup - ERROR - 组件注册运行发生异常:'HardwareCompetitionDataSender' object has no attribute 'set_receiver_transponder'
Traceback (most recent call last):
  File "F:\hardSoft\app\Collector\ApplicationFramework\launcher\Launcher.py", line 89, in startup
    await self.__application_task
  File "F:\hardSoft\app\Collector\Collector/application\ApplicationImplement.py", line 155, in run
    await self.__receiver_manager.startup()
  File "F:\hardSoft\app\Collector\Collector\service\ReceiverManager.py", line 45, in startup
    instance.set_receiver_transponder(self.__business_manager)
AttributeError: 'HardwareCompetitionDataSender' object has no attribute 'set_receiver_transponder'
